<?xml version="1.0" ?>
<robot name="humanoid_robot">

  <!-- Define robot links -->
  <link name="torso">
    <visual>
      <geometry>
        <box size="0.2 0.2 0.4"/>
      </geometry>
      <material name="blue">
        <color rgba="0 0 1 1"/>
      </material>
    </visual>
  </link>

  <link name="head">
    <visual>
      <geometry>
        <sphere radius="0.1"/>
      </geometry>
      <material name="red">
        <color rgba="1 0 0 1"/>
      </material>
    </visual>
  </link>

  <link name="left_arm">
    <visual>
      <geometry>
        <cylinder radius="0.05" length="0.5"/>
      </geometry>
      <material name="green">
        <color rgba="0 1 0 1"/>
      </material>
    </visual>
  </link>

  <link name="right_arm">
    <visual>
      <geometry>
        <cylinder radius="0.05" length="0.5"/>
      </geometry>
      <material name="green">
        <color rgba="0 1 0 1"/>
      </material>
    </visual>
  </link>

  <link name="left_leg">
    <visual>
      <geometry>
        <cylinder radius="0.1" length="0.6"/>
      </geometry>
      <material name="yellow">
        <color rgba="1 1 0 1"/>
      </material>
    </visual>
  </link>

  <link name="right_leg">
    <visual>
      <geometry>
        <cylinder radius="0.1" length="0.6"/>
      </geometry>
      <material name="yellow">
        <color rgba="1 1 0 1"/>
      </material>
    </visual>
  </link>

  <!-- Define robot joints -->
  <joint name="torso_to_head" type="fixed">
    <parent link="torso"/>
    <child link="head"/>
    <origin xyz="0 0 0.2"/>
  </joint>

  <joint name="torso_to_left_arm" type="revolute">
    <parent link="torso"/>
    <child link="left_arm"/>
    <origin xyz="-0.2 0 0.2"/>
    <axis xyz="0 0 1"/>
    <limit effort="10" lower="-1.5708" upper="1.5708" velocity="1"/>
  </joint>

  <joint name="torso_to_right_arm" type="revolute">
    <parent link="torso"/>
    <child link="right_arm"/>
    <origin xyz="0.2 0 0.2"/>
    <axis xyz="0 0 1"/>
    <limit effort="10" lower="-1.5708" upper="1.5708" velocity="1"/>
  </joint>

  <joint name="torso_to_left_leg" type="revolute">
    <parent link="torso"/>
    <child link="left_leg"/>
    <origin xyz="-0.1 0 -0.2"/>
    <axis xyz="0 0 1"/>
    <limit effort="10" lower="-1.5708" upper="1.5708" velocity="1"/>
  </joint>

  <joint name="torso_to_right_leg" type="revolute">
<parent link="torso"/>
<child link="right_leg"/>
<origin xyz="0.1 0 -0.2"/>
<axis xyz="0 0 1"/>
<limit effort="10" lower="-1.5708" upper="1.5708" velocity="1"/>
</joint>

</robot>
